2025-07-04 16:40:29 | ERROR    | app.services.knowledge.page_analysis_kb:get_page_types_summary:197 | 获取页面类型统计失败: __aenter__
2025-07-04 16:40:49 | ERROR    | app.services.knowledge.page_analysis_kb:search_similar_pages:96 | 搜索相似页面失败: __aenter__
2025-07-04 16:41:15 | ERROR    | app.services.knowledge.page_analysis_kb:get_page_types_summary:197 | 获取页面类型统计失败: __aenter__
2025-07-04 16:41:36 | ERROR    | app.services.knowledge.page_analysis_kb:get_page_types_summary:197 | 获取页面类型统计失败: __aenter__
2025-07-04 16:42:51 | ERROR    | app.services.knowledge.page_analysis_kb:get_page_types_summary:197 | 获取页面类型统计失败: __aenter__
2025-07-04 16:42:51 | ERROR    | app.services.knowledge.page_analysis_kb:get_page_types_summary:197 | 获取页面类型统计失败: __aenter__
2025-07-04 16:44:22 | ERROR    | app.services.knowledge.page_analysis_kb:get_page_types_summary:197 | 获取页面类型统计失败: __aenter__
2025-07-04 16:44:45 | ERROR    | app.services.knowledge.page_analysis_kb:get_page_types_summary:197 | 获取页面类型统计失败: __aenter__
2025-07-04 16:49:46 | ERROR    | app.services.knowledge.page_analysis_kb:get_page_types_summary:200 | 获取页面类型统计失败: __aenter__
2025-07-04 16:50:48 | ERROR    | app.services.knowledge.page_analysis_kb:get_page_types_summary:200 | 获取页面类型统计失败: __aenter__
2025-07-04 16:50:48 | ERROR    | app.services.knowledge.page_analysis_kb:get_page_types_summary:200 | 获取页面类型统计失败: __aenter__
2025-07-04 16:51:53 | ERROR    | app.services.knowledge.page_analysis_kb:get_page_types_summary:200 | 获取页面类型统计失败: __aenter__
2025-07-04 19:02:09 | ERROR    | app.database.connection:create_tables:76 | 数据库表创建失败: (sqlalchemy.dialects.postgresql.asyncpg.ProgrammingError) <class 'asyncpg.exceptions.DuplicateTableError'>: 关系 "idx_page_analysis_created_at" 已经存在
[SQL: CREATE INDEX idx_page_analysis_created_at ON page_analysis_results (created_at)]
(Background on this error at: https://sqlalche.me/e/20/f405)
2025-07-04 19:02:09 | ERROR    | app.core.database_startup:initialize_database_on_startup:46 | ❌ 数据库初始化失败: (sqlalchemy.dialects.postgresql.asyncpg.ProgrammingError) <class 'asyncpg.exceptions.DuplicateTableError'>: 关系 "idx_page_analysis_created_at" 已经存在
[SQL: CREATE INDEX idx_page_analysis_created_at ON page_analysis_results (created_at)]
(Background on this error at: https://sqlalche.me/e/20/f405)
2025-07-04 19:02:24 | ERROR    | app.database.connection:create_tables:76 | 数据库表创建失败: (sqlalchemy.dialects.postgresql.asyncpg.ProgrammingError) <class 'asyncpg.exceptions.DuplicateTableError'>: 关系 "idx_page_analysis_created_at" 已经存在
[SQL: CREATE INDEX idx_page_analysis_created_at ON page_analysis_results (created_at)]
(Background on this error at: https://sqlalche.me/e/20/f405)
2025-07-04 19:02:24 | ERROR    | app.core.database_startup:initialize_database_on_startup:46 | ❌ 数据库初始化失败: (sqlalchemy.dialects.postgresql.asyncpg.ProgrammingError) <class 'asyncpg.exceptions.DuplicateTableError'>: 关系 "idx_page_analysis_created_at" 已经存在
[SQL: CREATE INDEX idx_page_analysis_created_at ON page_analysis_results (created_at)]
(Background on this error at: https://sqlalche.me/e/20/f405)
2025-07-04 20:43:01 | ERROR    | app.database.connection:create_tables:76 | 数据库表创建失败: (sqlalchemy.dialects.postgresql.asyncpg.ProgrammingError) <class 'asyncpg.exceptions.DuplicateTableError'>: 关系 "idx_page_analysis_created_at" 已经存在
[SQL: CREATE INDEX idx_page_analysis_created_at ON page_analysis_results (created_at)]
(Background on this error at: https://sqlalche.me/e/20/f405)
2025-07-04 20:43:01 | ERROR    | app.core.database_startup:initialize_database_on_startup:46 | ❌ 数据库初始化失败: (sqlalchemy.dialects.postgresql.asyncpg.ProgrammingError) <class 'asyncpg.exceptions.DuplicateTableError'>: 关系 "idx_page_analysis_created_at" 已经存在
[SQL: CREATE INDEX idx_page_analysis_created_at ON page_analysis_results (created_at)]
(Background on this error at: https://sqlalche.me/e/20/f405)
2025-07-04 20:52:14 | ERROR    | app.services.web.orchestrator_service:analyze_page_elements:253 | 页面元素分析失败: 'WebOrchestrator' object has no attribute '_initialize_runtime'
2025-07-04 20:52:14 | ERROR    | app.services.web.orchestrator_service:analyze_page_elements:255 | 详细错误信息: Traceback (most recent call last):
  File "/Users/fairy/Desktop/Project/Platform_Demo/backend/app/services/web/orchestrator_service.py", line 229, in analyze_page_elements
    await self._initialize_runtime()
AttributeError: 'WebOrchestrator' object has no attribute '_initialize_runtime'

2025-07-04 20:53:12 | ERROR    | app.services.web.orchestrator_service:analyze_page_elements:253 | 页面元素分析失败: 'str' object has no attribute 'type'
2025-07-04 20:53:12 | ERROR    | app.services.web.orchestrator_service:analyze_page_elements:255 | 详细错误信息: Traceback (most recent call last):
  File "/Users/fairy/Desktop/Project/Platform_Demo/backend/app/services/web/orchestrator_service.py", line 244, in analyze_page_elements
    await self.runtime.send_message(
  File "/opt/homebrew/lib/python3.10/site-packages/autogen_core/_single_threaded_agent_runtime.py", line 363, in send_message
    if recipient.type not in self._known_agent_names:
AttributeError: 'str' object has no attribute 'type'

2025-07-04 20:54:00 | ERROR    | app.agents.web.page_analyzer:_run_agent_analysis:132 | 团队分析执行失败: PageAnalyzerAgent._parse_analysis_result() takes 2 positional arguments but 3 were given
